<?xml version="1.0" encoding="UTF-8"?><testrun name="TestReadFileService" project="file-sorting" tests="3" started="3" failures="0" errors="1" ignored="0">
  <testsuite name="com.saleshero.application.service.TestReadFileService" time="0.024">
    <testcase name="testNumberCountWhileRead" classname="com.saleshero.application.service.TestReadFileService" time="0.018"/>
    <testcase name="testReadingAFile" classname="com.saleshero.application.service.TestReadFileService" time="0.001"/>
    <testcase name="testExceptionThrownForReadingFile" classname="com.saleshero.application.service.TestReadFileService" time="0.005">
      <error>java.lang.Exception: Unexpected exception, expected&lt;java.io.FileNotFoundException&gt; but was&lt;java.lang.AssertionError&gt;&#13;
	at org.junit.internal.runners.statements.ExpectException.evaluate(ExpectException.java:28)&#13;
	at org.junit.rules.ExpectedException$ExpectedExceptionStatement.evaluate(ExpectedException.java:239)&#13;
	at org.junit.rules.RunRules.evaluate(RunRules.java:20)&#13;
	at org.junit.runners.ParentRunner.runLeaf(ParentRunner.java:325)&#13;
	at org.junit.runners.BlockJUnit4ClassRunner.runChild(BlockJUnit4ClassRunner.java:78)&#13;
	at org.junit.runners.BlockJUnit4ClassRunner.runChild(BlockJUnit4ClassRunner.java:57)&#13;
	at org.junit.runners.ParentRunner$3.run(ParentRunner.java:290)&#13;
	at org.junit.runners.ParentRunner$1.schedule(ParentRunner.java:71)&#13;
	at org.junit.runners.ParentRunner.runChildren(ParentRunner.java:288)&#13;
	at org.junit.runners.ParentRunner.access$000(ParentRunner.java:58)&#13;
	at org.junit.runners.ParentRunner$2.evaluate(ParentRunner.java:268)&#13;
	at org.junit.runners.ParentRunner.run(ParentRunner.java:363)&#13;
	at org.mockito.internal.runners.JUnit45AndHigherRunnerImpl.run(JUnit45AndHigherRunnerImpl.java:37)&#13;
	at org.mockito.runners.MockitoJUnitRunner.run(MockitoJUnitRunner.java:62)&#13;
	at org.eclipse.jdt.internal.junit4.runner.JUnit4TestReference.run(JUnit4TestReference.java:86)&#13;
	at org.eclipse.jdt.internal.junit.runner.TestExecution.run(TestExecution.java:38)&#13;
	at org.eclipse.jdt.internal.junit.runner.RemoteTestRunner.runTests(RemoteTestRunner.java:459)&#13;
	at org.eclipse.jdt.internal.junit.runner.RemoteTestRunner.runTests(RemoteTestRunner.java:675)&#13;
	at org.eclipse.jdt.internal.junit.runner.RemoteTestRunner.run(RemoteTestRunner.java:382)&#13;
	at org.eclipse.jdt.internal.junit.runner.RemoteTestRunner.main(RemoteTestRunner.java:192)&#13;
Caused by: java.lang.AssertionError: expected exception was not occured.&#13;
	at org.junit.Assert.fail(Assert.java:88)&#13;
	at com.saleshero.application.service.TestReadFileService.testExceptionThrownForReadingFile(TestReadFileService.java:64)&#13;
	at sun.reflect.NativeMethodAccessorImpl.invoke0(Native Method)&#13;
	at sun.reflect.NativeMethodAccessorImpl.invoke(NativeMethodAccessorImpl.java:62)&#13;
	at sun.reflect.DelegatingMethodAccessorImpl.invoke(DelegatingMethodAccessorImpl.java:43)&#13;
	at java.lang.reflect.Method.invoke(Method.java:498)&#13;
	at org.junit.runners.model.FrameworkMethod$1.runReflectiveCall(FrameworkMethod.java:50)&#13;
	at org.junit.internal.runners.model.ReflectiveCallable.run(ReflectiveCallable.java:12)&#13;
	at org.junit.runners.model.FrameworkMethod.invokeExplosively(FrameworkMethod.java:47)&#13;
	at org.junit.internal.runners.statements.InvokeMethod.evaluate(InvokeMethod.java:17)&#13;
	at org.junit.internal.runners.statements.ExpectException.evaluate(ExpectException.java:19)&#13;
	... 19 more&#13;
&#13;
</error>
    </testcase>
  </testsuite>
</testrun>
